<?xml version="1.0" ?>
<robot name="bot5" xmlns:xacro="http://www.ros.org/wiki/xacro">

<xacro:include filename="$(find bot5_description)/urdf/materials.xacro" />
<xacro:include filename="$(find bot5_description)/urdf/bot5.trans" />
<xacro:include filename="$(find bot5_description)/urdf/bot5.gazebo" />
  
<link name="dummy"/>  
<link name="base_link">
  <inertial>
    <origin xyz="-0.1758856312258705 -0.0002108801413928246 0.15999684267558398" rpy="0 0 0"/>
    <mass value="8.70709040372319"/>
    <inertia ixx="0.077475" iyy="0.211713" izz="0.269158" ixy="0.000108" iyz="-1.7e-05" ixz="-0.006764"/>
  </inertial>
  <visual>
    <origin xyz="0 0 0" rpy="0 0 0"/>
    <geometry>
      <mesh filename="package://bot5_description/meshes/base_link.stl" scale="0.001 0.001 0.001"/>
    </geometry>
    <material name="silver"/>
  </visual>
  <collision>
    <origin xyz="0 0 0" rpy="0 0 0"/>
    <geometry>
      <mesh filename="package://bot5_description/meshes/base_link.stl" scale="0.001 0.001 0.001"/>
    </geometry>
  </collision>
</link>
  
<joint name="dummy_joint" type="fixed">
 <parent link="dummy"/>
 <child link="base_footprint"/>
</joint>

<link name="left_wheel">
  <inertial>
    <origin xyz="0.20004860168806374 0.03873115898033333 -4.449218771185315e-14" rpy="0 0 0"/>
    <mass value="2.1920210431083533"/>
    <inertia ixx="0.008637" iyy="0.016397" izz="0.008644" ixy="-3e-06" iyz="-0.0" ixz="-0.0"/>
  </inertial>
  <visual>
    <origin xyz="0.205931 -0.149879 -0.125" rpy="0 0 0"/>
    <geometry>
      <mesh filename="package://bot5_description/meshes/left_wheel_1.stl" scale="0.001 0.001 0.001"/>
    </geometry>
    <material name="silver"/>
  </visual>
  <collision>
    <origin xyz="0.205931 -0.149879 -0.125" rpy="0 0 0"/>
    <geometry>
      <mesh filename="package://bot5_description/meshes/left_wheel_1.stl" scale="0.001 0.001 0.001"/>
    </geometry>
  </collision>
</link>

<link name="right_wheel">
  <inertial>
    <origin xyz="0.20004860168807084 -0.03873122504117252 -4.4103609653234344e-14" rpy="0 0 0"/>
    <mass value="2.1920210431083507"/>
    <inertia ixx="0.008637" iyy="0.016397" izz="0.008644" ixy="3e-06" iyz="-0.0" ixz="-0.0"/>
  </inertial>
  <visual>
    <origin xyz="0.205931 0.150121 -0.125" rpy="0 0 0"/>
    <geometry>
      <mesh filename="package://bot5_description/meshes/right_wheel_1.stl" scale="0.001 0.001 0.001"/>
    </geometry>
    <material name="silver"/>
  </visual>
  <collision>
    <origin xyz="0.205931 0.150121 -0.125" rpy="0 0 0"/>
    <geometry>
      <mesh filename="package://bot5_description/meshes/right_wheel_1.stl" scale="0.001 0.001 0.001"/>
    </geometry>
  </collision>
</link>

<link name="caster_wheel_left_1">
  <inertial>
    <origin xyz="0.20000922655096387 -0.006899932525287894 -4.689106236903384e-06" rpy="0 0 0"/>
    <mass value="0.17837143544148457"/>
    <inertia ixx="0.00012" iyy="0.000221" izz="0.00012" ixy="-0.0" iyz="0.0" ixz="-0.0"/>
  </inertial>
  <visual>
    <origin xyz="0.61275 -0.105633 -0.049997" rpy="0 0 0"/>
    <geometry>
      <mesh filename="package://bot5_description/meshes/caster_wheel_left_1.stl" scale="0.001 0.001 0.001"/>
    </geometry>
    <material name="silver"/>
  </visual>
  <collision>
    <origin xyz="0.61275 -0.105633 -0.049997" rpy="0 0 0"/>
    <geometry>
      <mesh filename="package://bot5_description/meshes/caster_wheel_left_1.stl" scale="0.001 0.001 0.001"/>
    </geometry>
  </collision>
</link>

<link name="caster_body_left_1">
  <inertial>
    <origin xyz="-0.005218054493926039 -0.00010402054037038366 -0.017359128884011393" rpy="0 0 0"/>
    <mass value="0.6243519441999045"/>
    <inertia ixx="0.000602" iyy="0.000614" izz="0.00061" ixy="-2e-06" iyz="-4e-06" ixz="-0.000135"/>
  </inertial>
  <visual>
    <origin xyz="0.378931 -0.099879 -0.127652" rpy="0 0 0"/>
    <geometry>
      <mesh filename="package://bot5_description/meshes/caster_body_left_1.stl" scale="0.001 0.001 0.001"/>
    </geometry>
    <material name="silver"/>
  </visual>
  <collision>
    <origin xyz="0.378931 -0.099879 -0.127652" rpy="0 0 0"/>
    <geometry>
      <mesh filename="package://bot5_description/meshes/caster_body_left_1.stl" scale="0.001 0.001 0.001"/>
    </geometry>
  </collision>
</link>

<link name="caster_wheel_right_1">
  <inertial>
    <origin xyz="0.20000922655096454 0.005499857821771828 -4.68910623065838e-06" rpy="0 0 0"/>
    <mass value="0.1783714354414845"/>
    <inertia ixx="0.00012" iyy="0.000221" izz="0.00012" ixy="0.0" iyz="0.0" ixz="-0.0"/>
  </inertial>
  <visual>
    <origin xyz="0.61275 0.105875 -0.049997" rpy="0 0 0"/>
    <geometry>
      <mesh filename="package://bot5_description/meshes/caster_wheel_right_1.stl" scale="0.001 0.001 0.001"/>
    </geometry>
    <material name="silver"/>
  </visual>
  <collision>
    <origin xyz="0.61275 0.105875 -0.049997" rpy="0 0 0"/>
    <geometry>
      <mesh filename="package://bot5_description/meshes/caster_wheel_right_1.stl" scale="0.001 0.001 0.001"/>
    </geometry>
  </collision>
</link>

<link name="caster_body_right_1">
  <inertial>
    <origin xyz="-0.005218047430279149 0.00010393520480091178 -0.017359129924634106" rpy="0 0 0"/>
    <mass value="0.6243516912268836"/>
    <inertia ixx="0.000602" iyy="0.000614" izz="0.00061" ixy="2e-06" iyz="4e-06" ixz="-0.000135"/>
  </inertial>
  <visual>
    <origin xyz="0.378931 0.100121 -0.127652" rpy="0 0 0"/>
    <geometry>
      <mesh filename="package://bot5_description/meshes/caster_body_right_1.stl" scale="0.001 0.001 0.001"/>
    </geometry>
    <material name="silver"/>
  </visual>
  <collision>
    <origin xyz="0.378931 0.100121 -0.127652" rpy="0 0 0"/>
    <geometry>
      <mesh filename="package://bot5_description/meshes/caster_body_right_1.stl" scale="0.001 0.001 0.001"/>
    </geometry>
  </collision>
</link>

<link name="realsense_1">
  <inertial>
    <origin xyz="0.002098313288916971 0.0011644524543959218 0.01243779695699343" rpy="0 0 0"/>
    <mass value="0.09533442052024742"/>
    <inertia ixx="5.9e-05" iyy="9e-06" izz="6e-05" ixy="1e-06" iyz="-0.0" ixz="-0.0"/>
  </inertial>
  <visual>
    <origin xyz="-0.035069 0.000121 -0.223" rpy="0 0 0"/>
    <geometry>
      <mesh filename="package://bot5_description/meshes/realsense_1.stl" scale="0.001 0.001 0.001"/>
    </geometry>
    <material name="silver"/>
  </visual>
  <collision>
    <origin xyz="-0.035069 0.000121 -0.223" rpy="0 0 0"/>
    <geometry>
      <mesh filename="package://bot5_description/meshes/realsense_1.stl" scale="0.001 0.001 0.001"/>
    </geometry>
  </collision>
</link>

<link name="lidar_1">
  <inertial>
    <origin xyz="0.0001091440730938394 -1.1037922008845516e-05 0.015279585004613405" rpy="0 0 0"/>
    <mass value="0.3162775249943875"/>
    <inertia ixx="6e-05" iyy="6e-05" izz="6.5e-05" ixy="1e-06" iyz="-0.0" ixz="0.0"/>
  </inertial>
  <visual>
    <origin xyz="0.004809 0.000121 -0.277" rpy="0 0 0"/>
    <geometry>
      <mesh filename="package://bot5_description/meshes/lidar_1.stl" scale="0.001 0.001 0.001"/>
    </geometry>
    <material name="silver"/>
  </visual>
  <collision>
    <origin xyz="0.004809 0.000121 -0.277" rpy="0 0 0"/>
    <geometry>
      <mesh filename="package://bot5_description/meshes/lidar_1.stl" scale="0.001 0.001 0.001"/>
    </geometry>
  </collision>
</link>

<joint name="left_wheel" type="continuous">
  <origin xyz="-0.205931 0.149879 0.125" rpy="0 0 0"/>
  <parent link="base_link"/>
  <child link="left_wheel"/>
  <axis xyz="-0.0 1.0 -0.0"/>
</joint>

<joint name="right_wheel" type="continuous">
  <origin xyz="-0.205931 -0.150121 0.125" rpy="0 0 0"/>
  <parent link="base_link"/>
  <child link="right_wheel"/>
  <axis xyz="-0.0 1.0 -0.0"/>
</joint>

<joint name="Rev4" type="continuous">
  <origin xyz="-0.233819 0.005754 -0.077655" rpy="0 0 0"/>
  <parent link="caster_body_left_1"/>
  <child link="caster_wheel_left_1"/>
  <axis xyz="0.0 -1.0 0.0"/>
</joint>

<joint name="Rev5" type="continuous">
  <origin xyz="-0.378931 0.099879 0.127652" rpy="0 0 0"/>
  <parent link="base_link"/>
  <child link="caster_body_left_1"/>
  <axis xyz="0.0 0.0 1.0"/>
</joint>

<joint name="Rev6" type="continuous">
  <origin xyz="-0.233819 -0.005754 -0.077655" rpy="0 0 0"/>
  <parent link="caster_body_right_1"/>
  <child link="caster_wheel_right_1"/>
  <axis xyz="-0.0 -1.0 0.0"/>
</joint>

<joint name="Rev7" type="continuous">
  <origin xyz="-0.378931 -0.100121 0.127652" rpy="0 0 0"/>
  <parent link="base_link"/>
  <child link="caster_body_right_1"/>
  <axis xyz="0.0 0.0 1.0"/>
</joint>

<joint name="Rigid8" type="fixed">
  <origin xyz="0.035069 -0.000121 0.223" rpy="0 0 0"/>
  <parent link="base_link"/>
  <child link="realsense_1"/>
</joint>

<joint name="Rigid9" type="fixed">
  <origin xyz="-0.004809 -0.000121 0.277" rpy="0 0 0"/>
  <parent link="base_link"/>
  <child link="lidar_1"/>
</joint>

</robot>
