<?xml version="1.0" ?>
<robot name="bot5" xmlns:xacro="http://www.ros.org/wiki/xacro">

<xacro:include filename="$(find bot5_description)/urdf/materials.xacro" />
<xacro:include filename="$(find bot5_description)/urdf/bot5.trans" />
<xacro:include filename="$(find bot5_description)/urdf/bot5.gazebo" />
<link name="base_link">
  <inertial>
    <origin xyz="0.02069671382034613 -0.0002093679082253623 0.15444123169757432" rpy="0 0 0"/>
    <mass value="8.856157175485883"/>
    <inertia ixx="0.080412" iyy="0.219201" izz="0.276705" ixy="0.000111" iyz="-1.6e-05" ixz="-0.009514"/>
  </inertial>
  <visual>
    <origin xyz="0 0 0" rpy="0 0 0"/>
    <geometry>
      <mesh filename="package://bot5_description/meshes/base_link.stl" scale="0.001 0.001 0.001"/>
    </geometry>
    <material name="silver"/>
  </visual>
  <collision>
    <origin xyz="0 0 0" rpy="0 0 0"/>
    <geometry>
      <mesh filename="package://bot5_description/meshes/base_link.stl" scale="0.001 0.001 0.001"/>
    </geometry>
  </collision>
</link>

<link name="right_wheel_1">
  <inertial>
    <origin xyz="4.860168807077625e-05 -0.0537312250411725 -4.408973186542653e-14" rpy="0 0 0"/>
    <mass value="2.1920210431083507"/>
    <inertia ixx="0.008637" iyy="0.016397" izz="0.008644" ixy="3e-06" iyz="-0.0" ixz="-0.0"/>
  </inertial>
  <visual>
    <origin xyz="-0.194069 0.150121 -0.121" rpy="0 0 0"/>
    <geometry>
      <mesh filename="package://bot5_description/meshes/right_wheel_1.stl" scale="0.001 0.001 0.001"/>
    </geometry>
    <material name="silver"/>
  </visual>
  <collision>
    <origin xyz="-0.194069 0.150121 -0.121" rpy="0 0 0"/>
    <geometry>
      <mesh filename="package://bot5_description/meshes/right_wheel_1.stl" scale="0.001 0.001 0.001"/>
    </geometry>
  </collision>
</link>

<link name="left_wheel_1">
  <inertial>
    <origin xyz="4.860168806389287e-05 0.05373115898033334 -4.4325654258159375e-14" rpy="0 0 0"/>
    <mass value="2.1920210431083507"/>
    <inertia ixx="0.008637" iyy="0.016397" izz="0.008644" ixy="-3e-06" iyz="-0.0" ixz="0.0"/>
  </inertial>
  <visual>
    <origin xyz="-0.194069 -0.149879 -0.121" rpy="0 0 0"/>
    <geometry>
      <mesh filename="package://bot5_description/meshes/left_wheel_1.stl" scale="0.001 0.001 0.001"/>
    </geometry>
    <material name="silver"/>
  </visual>
  <collision>
    <origin xyz="-0.194069 -0.149879 -0.121" rpy="0 0 0"/>
    <geometry>
      <mesh filename="package://bot5_description/meshes/left_wheel_1.stl" scale="0.001 0.001 0.001"/>
    </geometry>
  </collision>
</link>

<link name="lidar_1">
  <inertial>
    <origin xyz="0.000109144073093842 -1.1037922008868067e-05 0.015279585004620178" rpy="0 0 0"/>
    <mass value="0.3162775249943875"/>
    <inertia ixx="6e-05" iyy="6e-05" izz="6.5e-05" ixy="1e-06" iyz="-0.0" ixz="0.0"/>
  </inertial>
  <visual>
    <origin xyz="-0.195191 0.000121 -0.273" rpy="0 0 0"/>
    <geometry>
      <mesh filename="package://bot5_description/meshes/lidar_1.stl" scale="0.001 0.001 0.001"/>
    </geometry>
    <material name="silver"/>
  </visual>
  <collision>
    <origin xyz="-0.195191 0.000121 -0.273" rpy="0 0 0"/>
    <geometry>
      <mesh filename="package://bot5_description/meshes/lidar_1.stl" scale="0.001 0.001 0.001"/>
    </geometry>
  </collision>
</link>

<link name="realsense_1">
  <inertial>
    <origin xyz="0.0020983132889169642 0.0011644524543959714 0.012437796954095914" rpy="0 0 0"/>
    <mass value="0.09533442052024746"/>
    <inertia ixx="5.9e-05" iyy="9e-06" izz="6e-05" ixy="1e-06" iyz="-0.0" ixz="-0.0"/>
  </inertial>
  <visual>
    <origin xyz="-0.235069 0.000121 -0.219" rpy="0 0 0"/>
    <geometry>
      <mesh filename="package://bot5_description/meshes/realsense_1.stl" scale="0.001 0.001 0.001"/>
    </geometry>
    <material name="silver"/>
  </visual>
  <collision>
    <origin xyz="-0.235069 0.000121 -0.219" rpy="0 0 0"/>
    <geometry>
      <mesh filename="package://bot5_description/meshes/realsense_1.stl" scale="0.001 0.001 0.001"/>
    </geometry>
  </collision>
</link>

<joint name="Rev1" type="continuous">
  <origin xyz="0.194069 -0.150121 0.121" rpy="0 0 0"/>
  <parent link="base_link"/>
  <child link="right_wheel_1"/>
  <axis xyz="-0.0 1.0 -0.0"/>
</joint>

<joint name="Rev2" type="continuous">
  <origin xyz="0.194069 0.149879 0.121" rpy="0 0 0"/>
  <parent link="base_link"/>
  <child link="left_wheel_1"/>
  <axis xyz="0.0 -1.0 0.0"/>
</joint>

<joint name="Rigid3" type="fixed">
  <origin xyz="0.195191 -0.000121 0.273" rpy="0 0 0"/>
  <parent link="base_link"/>
  <child link="lidar_1"/>
</joint>

<joint name="Rigid4" type="fixed">
  <origin xyz="0.235069 -0.000121 0.219" rpy="0 0 0"/>
  <parent link="base_link"/>
  <child link="realsense_1"/>
</joint>

</robot>
