<?xml version="1.0" ?>
<robot name="bot5" xmlns:xacro="http://www.ros.org/wiki/xacro">

<xacro:include filename="$(find bot5_description)/urdf/materials.xacro" />
<xacro:include filename="$(find bot5_description)/urdf/bot5.trans" />
<xacro:include filename="$(find bot5_description)/urdf/bot5.gazebo" />
<link name="base_link">
  <inertial>
    <origin xyz="-0.16988563122587064 -0.00021088014139281883 0.15999684267558392" rpy="0 0 0"/>
    <mass value="8.707090403723189"/>
    <inertia ixx="0.077475" iyy="0.211713" izz="0.269158" ixy="0.000108" iyz="-1.7e-05" ixz="-0.006764"/>
  </inertial>
  <visual>
    <origin xyz="0 0 0" rpy="0 0 0"/>
    <geometry>
      <mesh filename="package://bot5_description/meshes/base_link.stl" scale="0.001 0.001 0.001"/>
    </geometry>
    <material name="silver"/>
  </visual>
  <collision>
    <origin xyz="0 0 0" rpy="0 0 0"/>
    <geometry>
      <mesh filename="package://bot5_description/meshes/base_link.stl" scale="0.001 0.001 0.001"/>
    </geometry>
  </collision>
</link>

<link name="left_wheel">
  <inertial>
    <origin xyz="4.860168806373845e-05 0.03933115898033335 -4.4422798772814076e-14" rpy="0 0 0"/>
    <mass value="2.1920210431083516"/>
    <inertia ixx="0.008637" iyy="0.016397" izz="0.008644" ixy="-3e-06" iyz="-0.0" ixz="-0.0"/>
  </inertial>
  <visual>
    <origin xyz="-6.9e-05 -0.149879 -0.125" rpy="0 0 0"/>
    <geometry>
      <mesh filename="package://bot5_description/meshes/left_wheel_1.stl" scale="0.001 0.001 0.001"/>
    </geometry>
    <material name="silver"/>
  </visual>
  <collision>
    <origin xyz="-6.9e-05 -0.149879 -0.125" rpy="0 0 0"/>
    <geometry>
      <mesh filename="package://bot5_description/meshes/left_wheel_1.stl" scale="0.001 0.001 0.001"/>
    </geometry>
  </collision>
</link>

<link name="right_wheel">
  <inertial>
    <origin xyz="4.860168807075394e-05 -0.039331225041172535 -4.4075854077618715e-14" rpy="0 0 0"/>
    <mass value="2.19202104310835"/>
    <inertia ixx="0.008637" iyy="0.016397" izz="0.008644" ixy="3e-06" iyz="-0.0" ixz="0.0"/>
  </inertial>
  <visual>
    <origin xyz="-6.9e-05 0.150121 -0.125" rpy="0 0 0"/>
    <geometry>
      <mesh filename="package://bot5_description/meshes/right_wheel_1.stl" scale="0.001 0.001 0.001"/>
    </geometry>
    <material name="silver"/>
  </visual>
  <collision>
    <origin xyz="-6.9e-05 0.150121 -0.125" rpy="0 0 0"/>
    <geometry>
      <mesh filename="package://bot5_description/meshes/right_wheel_1.stl" scale="0.001 0.001 0.001"/>
    </geometry>
  </collision>
</link>

<link name="caster_wheel_left_1">
  <inertial>
    <origin xyz="0.0010092265509636933 0.009499814127278974 -2.6891062368805674e-06" rpy="0 0 0"/>
    <mass value="0.17837143544148432"/>
    <inertia ixx="0.00012" iyy="0.000221" izz="0.00012" ixy="-0.0" iyz="0.0" ixz="-0.0"/>
  </inertial>
  <visual>
    <origin xyz="0.40775 -0.090375 -0.049995" rpy="0 0 0"/>
    <geometry>
      <mesh filename="package://bot5_description/meshes/caster_wheel_left_1.stl" scale="0.001 0.001 0.001"/>
    </geometry>
    <material name="silver"/>
  </visual>
  <collision>
    <origin xyz="0.40775 -0.090375 -0.049995" rpy="0 0 0"/>
    <geometry>
      <mesh filename="package://bot5_description/meshes/caster_wheel_left_1.stl" scale="0.001 0.001 0.001"/>
    </geometry>
  </collision>
</link>

<link name="caster_wheel_right_1">
  <inertial>
    <origin xyz="0.001009226550964637 0.0064998578217721065 -2.6891062306563795e-06" rpy="0 0 0"/>
    <mass value="0.17837143544148432"/>
    <inertia ixx="0.00012" iyy="0.000221" izz="0.00012" ixy="0.0" iyz="0.0" ixz="-0.0"/>
  </inertial>
  <visual>
    <origin xyz="0.40775 0.105875 -0.049995" rpy="0 0 0"/>
    <geometry>
      <mesh filename="package://bot5_description/meshes/caster_wheel_right_1.stl" scale="0.001 0.001 0.001"/>
    </geometry>
    <material name="silver"/>
  </visual>
  <collision>
    <origin xyz="0.40775 0.105875 -0.049995" rpy="0 0 0"/>
    <geometry>
      <mesh filename="package://bot5_description/meshes/caster_wheel_right_1.stl" scale="0.001 0.001 0.001"/>
    </geometry>
  </collision>
</link>

<link name="caster_body_left_1">
  <inertial>
    <origin xyz="-0.005217973578296842 -0.00010402054037036979 -0.01735912888504658" rpy="0 0 0"/>
    <mass value="0.6243519441999069"/>
    <inertia ixx="0.000602" iyy="0.000614" izz="0.000611" ixy="-2e-06" iyz="-4e-06" ixz="-0.000135"/>
  </inertial>
  <visual>
    <origin xyz="0.372931 -0.099879 -0.127652" rpy="0 0 0"/>
    <geometry>
      <mesh filename="package://bot5_description/meshes/caster_body_left_1.stl" scale="0.001 0.001 0.001"/>
    </geometry>
    <material name="silver"/>
  </visual>
  <collision>
    <origin xyz="0.372931 -0.099879 -0.127652" rpy="0 0 0"/>
    <geometry>
      <mesh filename="package://bot5_description/meshes/caster_body_left_1.stl" scale="0.001 0.001 0.001"/>
    </geometry>
  </collision>
</link>

<link name="caster_body_right_1">
  <inertial>
    <origin xyz="-0.005217966514615924 0.00010393520480088403 -0.017359129925669334" rpy="0 0 0"/>
    <mass value="0.6243516912268843"/>
    <inertia ixx="0.000602" iyy="0.000614" izz="0.000611" ixy="2e-06" iyz="4e-06" ixz="-0.000135"/>
  </inertial>
  <visual>
    <origin xyz="0.372931 0.100121 -0.127652" rpy="0 0 0"/>
    <geometry>
      <mesh filename="package://bot5_description/meshes/caster_body_right_1.stl" scale="0.001 0.001 0.001"/>
    </geometry>
    <material name="silver"/>
  </visual>
  <collision>
    <origin xyz="0.372931 0.100121 -0.127652" rpy="0 0 0"/>
    <geometry>
      <mesh filename="package://bot5_description/meshes/caster_body_right_1.stl" scale="0.001 0.001 0.001"/>
    </geometry>
  </collision>
</link>

<link name="realsense">
  <inertial>
    <origin xyz="0.006048313146213111 0.0011644524543970541 0.012437796956994596" rpy="0 0 0"/>
    <mass value="0.09533442052024729"/>
    <inertia ixx="5.9e-05" iyy="9e-06" izz="6e-05" ixy="1e-06" iyz="-0.0" ixz="-0.0"/>
  </inertial>
  <visual>
    <origin xyz="-0.034069 0.000121 -0.223" rpy="0 0 0"/>
    <geometry>
      <mesh filename="package://bot5_description/meshes/realsense_1.stl" scale="0.001 0.001 0.001"/>
    </geometry>
    <material name="silver"/>
  </visual>
  <collision>
    <origin xyz="-0.034069 0.000121 -0.223" rpy="0 0 0"/>
    <geometry>
      <mesh filename="package://bot5_description/meshes/realsense_1.stl" scale="0.001 0.001 0.001"/>
    </geometry>
  </collision>
</link>

<link name="imu">
  <inertial>
    <origin xyz="1.9553994023285837e-07 -3.303041936634414e-08 0.001000001415556534" rpy="0 0 0"/>
    <mass value="1.5700000467896408e-05"/>
    <inertia ixx="0.0" iyy="0.0" izz="0.0" ixy="-0.0" iyz="-0.0" ixz="0.0"/>
  </inertial>
  <visual>
    <origin xyz="-0.041069 0.000121 -0.223" rpy="0 0 0"/>
    <geometry>
      <mesh filename="package://bot5_description/meshes/imu_1.stl" scale="0.001 0.001 0.001"/>
    </geometry>
    <material name="silver"/>
  </visual>
  <collision>
    <origin xyz="-0.041069 0.000121 -0.223" rpy="0 0 0"/>
    <geometry>
      <mesh filename="package://bot5_description/meshes/imu_1.stl" scale="0.001 0.001 0.001"/>
    </geometry>
  </collision>
</link>

<link name="lidar">
  <inertial>
    <origin xyz="0.0001091440734231734 -1.1037922009016115e-05 0.01727958500461163" rpy="0 0 0"/>
    <mass value="0.3162775249943877"/>
    <inertia ixx="6e-05" iyy="6e-05" izz="6.5e-05" ixy="1e-06" iyz="-0.0" ixz="0.0"/>
  </inertial>
  <visual>
    <origin xyz="-0.001191 0.000121 -0.277" rpy="0 0 0"/>
    <geometry>
      <mesh filename="package://bot5_description/meshes/lidar_1.stl" scale="0.001 0.001 0.001"/>
    </geometry>
    <material name="silver"/>
  </visual>
  <collision>
    <origin xyz="-0.001191 0.000121 -0.277" rpy="0 0 0"/>
    <geometry>
      <mesh filename="package://bot5_description/meshes/lidar_1.stl" scale="0.001 0.001 0.001"/>
    </geometry>
  </collision>
</link>

<joint name="left_wheel" type="continuous">
  <origin xyz="6.9e-05 0.149879 0.125" rpy="0 0 0"/>
  <parent link="base_link"/>
  <child link="left_wheel"/>
  <axis xyz="-0.0 1.0 -0.0"/>
</joint>

<joint name="right_wheel" type="continuous">
  <origin xyz="6.9e-05 -0.150121 0.125" rpy="0 0 0"/>
  <parent link="base_link"/>
  <child link="right_wheel"/>
  <axis xyz="-0.0 1.0 -0.0"/>
</joint>

<joint name="left_caster_wheel" type="continuous">
  <origin xyz="-0.034819 -0.009504 -0.077657" rpy="0 0 0"/>
  <parent link="caster_body_left_1"/>
  <child link="caster_wheel_left_1"/>
  <axis xyz="0.0 -1.0 0.0"/>
</joint>

<joint name="right_caster_wheel" type="continuous">
  <origin xyz="-0.034819 -0.005754 -0.077657" rpy="0 0 0"/>
  <parent link="caster_body_right_1"/>
  <child link="caster_wheel_right_1"/>
  <axis xyz="-0.0 -1.0 0.0"/>
</joint>

<joint name="left_caster_body" type="continuous">
  <origin xyz="-0.372931 0.099879 0.127652" rpy="0 0 0"/>
  <parent link="base_link"/>
  <child link="caster_body_left_1"/>
  <axis xyz="0.0 0.0 1.0"/>
</joint>

<joint name="right_caster_body" type="continuous">
  <origin xyz="-0.372931 -0.100121 0.127652" rpy="0 0 0"/>
  <parent link="base_link"/>
  <child link="caster_body_right_1"/>
  <axis xyz="0.0 0.0 1.0"/>
</joint>

<joint name="realsense" type="fixed">
  <origin xyz="0.034069 -0.000121 0.223" rpy="0 0 0"/>
  <parent link="base_link"/>
  <child link="realsense"/>
</joint>

<joint name="imu" type="fixed">
  <origin xyz="0.041069 -0.000121 0.223" rpy="0 0 0"/>
  <parent link="base_link"/>
  <child link="imu"/>
</joint>

<joint name="lidar" type="fixed">
  <origin xyz="0.001191 -0.000121 0.277" rpy="0 0 0"/>
  <parent link="base_link"/>
  <child link="lidar"/>
</joint>

</robot>
