<?xml version="1.0" ?>
<robot name="urdf_bot5" xmlns:xacro="http://www.ros.org/wiki/xacro">

<xacro:include filename="$(find urdf_bot5_description)/urdf/materials.xacro" />
<xacro:include filename="$(find urdf_bot5_description)/urdf/urdf_bot5.trans" />
<xacro:include filename="$(find urdf_bot5_description)/urdf/urdf_bot5.gazebo" />
<link name="base_link">
  <inertial>
    <origin xyz="-0.16590307553971642 -0.0002108880005476036 0.15999861454116285" rpy="0 0 0"/>
    <mass value="8.706328839095804"/>
    <inertia ixx="0.076804" iyy="0.211673" izz="0.268452" ixy="0.000108" iyz="-1.7e-05" ixz="-0.006767"/>
  </inertial>
  <visual>
    <origin xyz="0 0 0" rpy="0 0 0"/>
    <geometry>
      <mesh filename="package://urdf_bot5_description/meshes/base_link.stl" scale="0.001 0.001 0.001"/>
    </geometry>
    <material name="silver"/>
  </visual>
  <collision>
    <origin xyz="0 0 0" rpy="0 0 0"/>
    <geometry>
      <mesh filename="package://urdf_bot5_description/meshes/base_link.stl" scale="0.001 0.001 0.001"/>
    </geometry>
  </collision>
</link>

<link name="left_wheel_1">
  <inertial>
    <origin xyz="-0.18633062523741925 0.19711935137048378 -0.12900000000000075" rpy="0 0 0"/>
    <mass value="2.2023455245607204"/>
    <inertia ixx="0.008708" iyy="0.016398" izz="0.008714" ixy="-3e-06" iyz="0.0" ixz="0.0"/>
  </inertial>
  <visual>
    <origin xyz="-0.190448 0.00419 -0.254" rpy="0 0 0"/>
    <geometry>
      <mesh filename="package://urdf_bot5_description/meshes/left_wheel_1.stl" scale="0.001 0.001 0.001"/>
    </geometry>
    <material name="silver"/>
  </visual>
  <collision>
    <origin xyz="-0.190448 0.00419 -0.254" rpy="0 0 0"/>
    <geometry>
      <mesh filename="package://urdf_bot5_description/meshes/left_wheel_1.stl" scale="0.001 0.001 0.001"/>
    </geometry>
  </collision>
</link>

<link name="right_wheel_1">
  <inertial>
    <origin xyz="0.08066937476258206 -0.188981417431324 -0.12900000000000061" rpy="0 0 0"/>
    <mass value="2.2023455245607204"/>
    <inertia ixx="0.008708" iyy="0.016398" izz="0.008714" ixy="3e-06" iyz="0.0" ixz="0.0"/>
  </inertial>
  <visual>
    <origin xyz="0.076552 0.00419 -0.254" rpy="0 0 0"/>
    <geometry>
      <mesh filename="package://urdf_bot5_description/meshes/right_wheel_1.stl" scale="0.001 0.001 0.001"/>
    </geometry>
    <material name="silver"/>
  </visual>
  <collision>
    <origin xyz="0.076552 0.00419 -0.254" rpy="0 0 0"/>
    <geometry>
      <mesh filename="package://urdf_bot5_description/meshes/right_wheel_1.stl" scale="0.001 0.001 0.001"/>
    </geometry>
  </collision>
</link>

<link name="left_caster_body_1">
  <inertial>
    <origin xyz="-0.5322145860041133 -0.2690573887165947 -0.1465903214507419" rpy="0 0 0"/>
    <mass value="0.5142158327053549"/>
    <inertia ixx="0.00052" iyy="0.000528" izz="0.000509" ixy="-2e-06" iyz="-4e-06" ixz="-0.000124"/>
  </inertial>
  <visual>
    <origin xyz="-0.156948 -0.36881 -0.258" rpy="0 0 0"/>
    <geometry>
      <mesh filename="package://urdf_bot5_description/meshes/left_caster_body_1.stl" scale="0.001 0.001 0.001"/>
    </geometry>
    <material name="silver"/>
  </visual>
  <collision>
    <origin xyz="-0.156948 -0.36881 -0.258" rpy="0 0 0"/>
    <geometry>
      <mesh filename="package://urdf_bot5_description/meshes/left_caster_body_1.stl" scale="0.001 0.001 0.001"/>
    </geometry>
  </collision>
</link>

<link name="right_caster_body'_1">
  <inertial>
    <origin xyz="-0.3322145901054461 -0.46880468301843786 -0.146590320198847" rpy="0 0 0"/>
    <mass value="0.514215936265926"/>
    <inertia ixx="0.00052" iyy="0.000528" izz="0.000509" ixy="2e-06" iyz="4e-06" ixz="-0.000124"/>
  </inertial>
  <visual>
    <origin xyz="0.043052 -0.36881 -0.258" rpy="0 0 0"/>
    <geometry>
      <mesh filename="package://urdf_bot5_description/meshes/right_caster_body'_1.stl" scale="0.001 0.001 0.001"/>
    </geometry>
    <material name="silver"/>
  </visual>
  <collision>
    <origin xyz="0.043052 -0.36881 -0.258" rpy="0 0 0"/>
    <geometry>
      <mesh filename="package://urdf_bot5_description/meshes/right_caster_body'_1.stl" scale="0.001 0.001 0.001"/>
    </geometry>
  </collision>
</link>

<link name="right_caster_wheel_1">
  <inertial>
    <origin xyz="-0.35393477344900476 -0.6940041421782285 -0.13035015857562834" rpy="0 0 0"/>
    <mass value="0.17837143544148437"/>
    <inertia ixx="0.00012" iyy="0.000221" izz="0.00012" ixy="0.0" iyz="0.0" ixz="-0.0"/>
  </inertial>
  <visual>
    <origin xyz="0.048806 -0.592629 -0.18484" rpy="0 0 0"/>
    <geometry>
      <mesh filename="package://urdf_bot5_description/meshes/right_caster_wheel_1.stl" scale="0.001 0.001 0.001"/>
    </geometry>
    <material name="silver"/>
  </visual>
  <collision>
    <origin xyz="0.048806 -0.592629 -0.18484" rpy="0 0 0"/>
    <geometry>
      <mesh filename="package://urdf_bot5_description/meshes/right_caster_wheel_1.stl" scale="0.001 0.001 0.001"/>
    </geometry>
  </collision>
</link>

<link name="left_caster_wheel_1">
  <inertial>
    <origin xyz="-0.5654427734490057 0.6920040674747117 -0.02136515857562906" rpy="0 0 0"/>
    <mass value="0.1783714354414844"/>
    <inertia ixx="0.00012" iyy="0.000221" izz="0.00012" ixy="-0.0" iyz="-0.0" ixz="-0.0"/>
  </inertial>
  <visual>
    <origin xyz="-0.162702 0.592871 -0.075855" rpy="0 0 0"/>
    <geometry>
      <mesh filename="package://urdf_bot5_description/meshes/left_caster_wheel_1.stl" scale="0.001 0.001 0.001"/>
    </geometry>
    <material name="silver"/>
  </visual>
  <collision>
    <origin xyz="-0.162702 0.592871 -0.075855" rpy="0 0 0"/>
    <geometry>
      <mesh filename="package://urdf_bot5_description/meshes/left_caster_wheel_1.stl" scale="0.001 0.001 0.001"/>
    </geometry>
  </collision>
</link>

<link name="D300Lidar_1">
  <inertial>
    <origin xyz="0.0001091440735400866 -1.1037922010429698e-05 0.01527958500487342" rpy="0 0 0"/>
    <mass value="0.3162775249943886"/>
    <inertia ixx="6e-05" iyy="6e-05" izz="6.5e-05" ixy="1e-06" iyz="-0.0" ixz="0.0"/>
  </inertial>
  <visual>
    <origin xyz="-0.005191 0.000121 -0.277" rpy="0 0 0"/>
    <geometry>
      <mesh filename="package://urdf_bot5_description/meshes/D300Lidar_1.stl" scale="0.001 0.001 0.001"/>
    </geometry>
    <material name="silver"/>
  </visual>
  <collision>
    <origin xyz="-0.005191 0.000121 -0.277" rpy="0 0 0"/>
    <geometry>
      <mesh filename="package://urdf_bot5_description/meshes/D300Lidar_1.stl" scale="0.001 0.001 0.001"/>
    </geometry>
  </collision>
</link>

<link name="Realsense_1">
  <inertial>
    <origin xyz="0.00209831310783698 0.0011644524544826825 0.012437796786444327" rpy="0 0 0"/>
    <mass value="0.09533442052024718"/>
    <inertia ixx="5.9e-05" iyy="9e-06" izz="6e-05" ixy="1e-06" iyz="-0.0" ixz="-0.0"/>
  </inertial>
  <visual>
    <origin xyz="-0.045069 0.000121 -0.223" rpy="0 0 0"/>
    <geometry>
      <mesh filename="package://urdf_bot5_description/meshes/Realsense_1.stl" scale="0.001 0.001 0.001"/>
    </geometry>
    <material name="silver"/>
  </visual>
  <collision>
    <origin xyz="-0.045069 0.000121 -0.223" rpy="0 0 0"/>
    <geometry>
      <mesh filename="package://urdf_bot5_description/meshes/Realsense_1.stl" scale="0.001 0.001 0.001"/>
    </geometry>
  </collision>
</link>

<joint name="Rev1" type="continuous">
  <origin xyz="0.190448 -0.00419 0.254" rpy="0 0 0"/>
  <parent link="base_link"/>
  <child link="left_wheel_1"/>
  <axis xyz="-0.0 1.0 -0.0"/>
</joint>

<joint name="Rev2" type="continuous">
  <origin xyz="-0.076552 -0.00419 0.254" rpy="0 0 0"/>
  <parent link="base_link"/>
  <child link="right_wheel_1"/>
  <axis xyz="-0.0 1.0 -0.0"/>
</joint>

<joint name="Rev3" type="continuous">
  <origin xyz="0.156948 0.36881 0.258" rpy="0 0 0"/>
  <parent link="base_link"/>
  <child link="left_caster_body_1"/>
  <axis xyz="-0.0 -0.0 -1.0"/>
</joint>

<joint name="Rev4" type="continuous">
  <origin xyz="-0.043052 0.36881 0.258" rpy="0 0 0"/>
  <parent link="base_link"/>
  <child link="right_caster_body'_1"/>
  <axis xyz="-0.0 -0.0 -1.0"/>
</joint>

<joint name="Rev5" type="continuous">
  <origin xyz="-0.005754 0.223819 -0.07316" rpy="0 0 0"/>
  <parent link="right_caster_body'_1"/>
  <child link="right_caster_wheel_1"/>
  <axis xyz="-0.0 -1.0 0.0"/>
</joint>

<joint name="Rev6" type="continuous">
  <origin xyz="0.005754 -0.961681 -0.182145" rpy="0 0 0"/>
  <parent link="left_caster_body_1"/>
  <child link="left_caster_wheel_1"/>
  <axis xyz="0.0 -1.0 0.0"/>
</joint>

<joint name="Rigid7" type="fixed">
  <origin xyz="0.005191 -0.000121 0.277" rpy="0 0 0"/>
  <parent link="base_link"/>
  <child link="D300Lidar_1"/>
</joint>

<joint name="Rigid8" type="fixed">
  <origin xyz="0.045069 -0.000121 0.223" rpy="0 0 0"/>
  <parent link="base_link"/>
  <child link="Realsense_1"/>
</joint>

</robot>
